Workbook

Sheet Dashboard
B2: 🪐 PLANET DATA VISUALIZATION DASHBOARD
B3: Exoplanet Mass & Radius Analytics • 5,986 Confirmed Planets • Source: Cleaned & Feature-Engineered Dataset
B6: TOTAL PLANETS | F6: HIGHEST MASS | J6: LOWEST MASS | N6: AVG. MASS
B7: =COUNTA('Cleaned Data'!$A$2:$A$5987) -> 5986 | F7: {=INDEX('Cleaned Data'!$A$2:$A$5987,MATCH(MAX('Cleaned Data'!$C$2:$C$5987),'Cleaned Data'!$C$2:$C$5987,0))&" ("&TEXT(MAX('Cleaned Data'!$C$2:$C$5987),"0.00")&" Mj)"} -> GJ 2030 Ac (12.93 Mj) | J7: {=INDEX('Cleaned Data'!$A$2:$A$5987,MATCH(MIN('Cleaned Data'!$C$2:$C$5987),'Cleaned Data'!$C$2:$C$5987,0))&" ("&TEXT(MIN('Cleaned Data'!$C$2:$C$5987),"0.00000")&" Mj)"} -> LHS 1678 b (0.00019 Mj) | N7: =AVERAGE('Cleaned Data'!$C$2:$C$5987) -> 1.4925385
B9: Confirmed exoplanets in dataset | F9: Most massive confirmed planet | J9: Least massive confirmed planet | N9: Mean across all measured planets
B11: AVG. RADIUS | E11: MEDIAN MASS | H11: MASS–RADIUS CORR. | K11: MASS DATA COVERAGE | N11: RADIUS DATA COVERAGE
B12: =AVERAGE('Cleaned Data'!$I$2:$I$5987) -> 0.40151504 | E12: =MEDIAN('Cleaned Data'!$C$2:$C$5987) -> 0.37 | H12: =CORREL('Cleaned Data'!$C$2:$C$5987,'Cleaned Data'!$I$2:$I$5987) -> 0.41728603 | K12: =COUNT('Cleaned Data'!$C$2:$C$5987)/COUNTA('Cleaned Data'!$A$2:$A$5987) -> 0.34731039 | N12: =COUNT('Cleaned Data'!$I$2:$I$5987)/COUNTA('Cleaned Data'!$A$2:$A$5987) -> 0.76311393
B14: Mean radius, Jupiter units | E14: Robust central tendency | H14: Pearson correlation coefficient | K14: Planets with measured mass | N14: Planets with measured radius
B15: EXOPLANET EXPLORER
B17: Distribution & Composition
B35: Top Planets by Size
B53: Relationships & Data Quality
B71: Key Findings & Data Notes
B72: ="• Dataset covers "&TEXT(COUNTA('Cleaned Data'!$A$2:$A$5987),"#,##0")&" confirmed exoplanets; every record carries planet_status = Confirmed." -> • Dataset covers 5,986 confirmed exoplanets; every record carries planet_status = Confirmed.
B74: {="• Most massive planet: "&INDEX('Cleaned Data'!$A$2:$A$5987,MATCH(MAX('Cleaned Data'!$C$2:$C$5987),'Cleaned Data'!$C$2:$C$5987,0))&" at "&TEXT(MAX('Cleaned Data'!$C$2:$C$5987),"0.000")&" Jupiter masses; least massive: "&INDEX('Cleaned Data'!$A$2:$A$5987,MATCH(MIN('Cleaned Data'!$C$2:$C$5987),'Cleaned Data'!$C$2:$C$5987,0))&" at "&TEXT(MIN('Cleaned Data'!$C$2:$C$5987),"0.00000")&" Jupiter masses."} -> • Most massive planet: GJ 2030 Ac at 12.934 Jupiter masses; least massive: LHS 1678 b at 0.00019 Jupiter masses.
B76: ="• Mean planet mass is "&TEXT(AVERAGE('Cleaned Data'!$C$2:$C$5987),"0.0000")&" Mj vs. a median of "&TEXT(MEDIAN('Cleaned Data'!$C$2:$C$5987),"0.0000")&" Mj — the large mean/median gap signals a right-skewed distribution driven by a minority of giant planets." -> • Mean planet mass is 1.4925 Mj vs. a median of 0.3700 Mj — the large mean/median gap signals a right-skewed distribution driven by a minority of giant planets.
B78: ="• Mass and radius show a moderate positive correlation (r = "&TEXT(CORREL('Cleaned Data'!$C$2:$C$5987,'Cleaned Data'!$I$2:$I$5987),"0.000")&"); bigger planets tend to be heavier, but the relationship is far from linear across the full mass range." -> • Mass and radius show a moderate positive correlation (r = 0.417); bigger planets tend to be heavier, but the relationship is far from linear across the full mass range.
B80: ="• Mass data is available for "&TEXT(COUNT('Cleaned Data'!$C$2:$C$5987)/COUNTA('Cleaned Data'!$A$2:$A$5987),"0.0%")&" of planets and radius for "&TEXT(COUNT('Cleaned Data'!$I$2:$I$5987)/COUNTA('Cleaned Data'!$A$2:$A$5987),"0.0%")&" — coverage gaps should be kept in mind when generalizing findings." -> • Mass data is available for 34.7% of planets and radius for 76.3% — coverage gaps should be kept in mind when generalizing findings.
B82: ="• IQR-based outlier screening flags "&TEXT(COUNTIF('Cleaned Data'!$K$2:$K$5987,TRUE())/COUNT('Cleaned Data'!$C$2:$C$5987),"0.0%")&" of mass values and "&TEXT(COUNTIF('Cleaned Data'!$M$2:$M$5987,TRUE())/COUNT('Cleaned Data'!$I$2:$I$5987),"0.0%")&" of radius values as statistical outliers — mostly ultra-massive or ultra-large planets." -> • IQR-based outlier screening flags 13.5% of mass values and 19.2% of radius values as statistical outliers — mostly ultra-massive or ultra-large planets.
B84: ="• See the Mass Classification and Radius Classification sheets for a full breakdown of planet types (Sub-Neptune through Super-Jupiter)." -> • See the Mass Classification and Radius Classification sheets for a full breakdown of planet types (Sub-Neptune through Super-Jupiter).
B87: Notes: Mass and radius are expressed in Jupiter units (Mj, Rj). Classification thresholds are approximate size bands for exploratory grouping, not formal planetary-science definitions. Outliers identified via the 1.5×IQR fence method. All KPI, chart, and classification values are live formulas linked to the 'Cleaned Data' sheet and recalculate automatically.
B88: Data Visualization & Dashboard | Cleaned Dataset Analysis
B91: HIGHEST MASS PLANET HATS-70 b Mass: 12.9000 | D91: LOWEST MASS PLANET LHS 1678 b Mass: 0.00019 | F91: AVERAGE MASS 0.9240 Jupiter masses | H91: AVERAGE RADIUS 0.7116 Jupiter radii | J91: VALID PLANETS 1,588 Mass + radius records
O113: KEY FINDINGS
O114: • Highest mass: HATS-70 b (12.9000)

Sheet Cleaned Data
A1: name | B1: planet_status | C1: mass | D1: mass_error_min | E1: mass_error_max | F1: mass_sini | G1: mass_sini_error_min | H1: mass_sini_error_max | I1: radius | J1: radius_error_min | K1: mass_outlier_flag | L1: mass_sini_outlier_flag | M1: radius_outlier_flag | N1: mass_log1p | O1: mass_sini_log1p | P1: radius_log1p | Q1: mass_zscore | R1: mass_sini_zscore | S1: radius_zscore | T1: mass_rank | U1: radius_rank
A2: 109 Psc b | B2: Confirmed | C2: 5.743 | D2: 0.289 | E2: 1.011 | F2: 6.383 | G2: 0.078 | H2: 0.078 | I2: 1.152 | K2: =TRUE() -> TRUE | L2: =TRUE() -> TRUE | M2: =TRUE() -> TRUE | N2: 1.9085049 | O2: 1.9991801 | P2: 0.76639764 | Q2: 2.8994105 | R2: 3.3971458 | S2: 0.61130805 | T2: =IF(C2="","",RANK(C2,$C$2:$C$5987)+COUNTIF($C$2:C2,C2)-1) -> 185 | U2: =IF(I2="","",RANK(I2,$I$2:$I$5987)+COUNTIF($I$2:I2,I2)-1) -> 447
A3: 112 Psc b | B3: Confirmed | D3: 0.005 | E3: 0.004 | F3: 0.033 | G3: 0.005 | H3: 0.004 | K3: =FALSE() -> FALSE | L3: =FALSE() -> FALSE | M3: =FALSE() -> FALSE | O3: 0.03246719 | T3: =IF(C3="","",RANK(C3,$C$2:$C$5987)+COUNTIF($C$2:C3,C3)-1) | U3: =IF(I3="","",RANK(I3,$I$2:$I$5987)+COUNTIF($I$2:I3,I3)-1)
A4: 112 Psc c | B4: Confirmed | C4: 9.866 | D4: 1.781 | E4: 3.19 | K4: =TRUE() -> TRUE | L4: =FALSE() -> FALSE | M4: =FALSE() -> FALSE | N4: 2.3856386 | T4: =IF(C4="","",RANK(C4,$C$2:$C$5987)+COUNTIF($C$2:C4,C4)-1) -> 61 | U4: =IF(I4="","",RANK(I4,$I$2:$I$5987)+COUNTIF($I$2:I4,I4)-1)
A5: 11 UMi b | B5: Confirmed | D5: 1.1 | E5: 1.1 | F5: 11.0873 | G5: 1.1 | H5: 1.1 | K5: =FALSE() -> FALSE | L5: =TRUE() -> TRUE | M5: =FALSE() -> FALSE | O5: 2.4921553 | T5: =IF(C5="","",RANK(C5,$C$2:$C$5987)+COUNTIF($C$2:C5,C5)-1) | U5: =IF(I5="","",RANK(I5,$I$2:$I$5987)+COUNTIF($I$2:I5,I5)-1)
A6: 14 And Ab | B6: Confirmed | D6: 0.23 | E6: 0.23 | F6: 4.684 | G6: 0.23 | H6: 0.23 | K6: =FALSE() -> FALSE | L6: =FALSE() -> FALSE | M6: =FALSE() -> FALSE | O6: 1.7376552 | T6: =IF(C6="","",RANK(C6,$C$2:$C$5987)+COUNTIF($C$2:C6,C6)-1) | U6: =IF(I6="","",RANK(I6,$I$2:$I$5987)+COUNTIF($I$2:I6,I6)-1)
A7: 14 Her b | B7: Confirmed | C7: 8.9 | D7: 1.7 | E7: 1.3 | F7: 4.95 | K7: =TRUE() -> TRUE | L7: =FALSE() -> FALSE | M7: =FALSE() -> FALSE | N7: 2.2925348 | O7: 1.7833912 | T7: =IF(C7="","",RANK(C7,$C$2:$C$5987)+COUNTIF($C$2:C7,C7)-1) -> 84 | U7: =IF(I7="","",RANK(I7,$I$2:$I$5987)+COUNTIF($I$2:I7,I7)-1)
A8: 14 Her c | B8: Confirmed | C8: 7.9 | D8: 1.2 | E8: 1.6 | F8: 7.12 | K8: =TRUE() -> TRUE | L8: =TRUE() -> TRUE | M8: =FALSE() -> FALSE | N8: 2.1860513 | O8: 2.0943302 | T8: =IF(C8="","",RANK(C8,$C$2:$C$5987)+COUNTIF($C$2:C8,C8)-1) -> 112 | U8: =IF(I8="","",RANK(I8,$I$2:$I$5987)+COUNTIF($I$2:I8,I8)-1)
A9: 16 Cyg Bb | B9: Confirmed | D9: 0.08 | E9: 0.08 | F9: 1.64 | G9: 0.08 | H9: 0.08 | K9: =FALSE() -> FALSE | L9: =FALSE() -> FALSE | M9: =FALSE() -> FALSE | O9: 0.97077892 | T9: =IF(C9="","",RANK(C9,$C$2:$C$5987)+COUNTIF($C$2:C9,C9)-1) | U9: =IF(I9="","",RANK(I9,$I$2:$I$5987)+COUNTIF($I$2:I9,I9)-1)
A10: 18 Del Ab | B10: Confirmed | D10: 0.36 | E10: 0.36 | F10: 10.3 | G10: 0.36 | H10: 0.36 | K10: =FALSE() -> FALSE | L10: =TRUE() -> TRUE | M10: =FALSE() -> FALSE | O10: 2.4248027 | T10: =IF(C10="","",RANK(C10,$C$2:$C$5987)+COUNTIF($C$2:C10,C10)-1) | U10: =IF(I10="","",RANK(I10,$I$2:$I$5987)+COUNTIF($I$2:I10,I10)-1)
A11: 23 Lib b | B11: Confirmed | D11: 0.02 | E11: 0.02 | F11: 1.59 | G11: 0.02 | H11: 0.02 | K11: =FALSE() -> FALSE | L11: =FALSE() -> FALSE | M11: =FALSE() -> FALSE | O11: 0.95165788 | T11: =IF(C11="","",RANK(C11,$C$2:$C$5987)+COUNTIF($C$2:C11,C11)-1) | U11: =IF(I11="","",RANK(I11,$I$2:$I$5987)+COUNTIF($I$2:I11,I11)-1)
A12: 23 Lib c | B12: Confirmed | D12: 0.03 | E12: 0.03 | F12: 0.82 | G12: 0.03 | H12: 0.03 | K12: =FALSE() -> FALSE | L12: =FALSE() -> FALSE | M12: =FALSE() -> FALSE | O12: 0.5988365 | T12: =IF(C12="","",RANK(C12,$C$2:$C$5987)+COUNTIF($C$2:C12,C12)-1) | U12: =IF(I12="","",RANK(I12,$I$2:$I$5987)+COUNTIF($I$2:I12,I12)-1)
A13: 24 Boo b | B13: Confirmed | D13: 0.11 | E13: 0.11 | F13: 0.91 | G13: 0.11 | H13: 0.11 | K13: =FALSE() -> FALSE | L13: =FALSE() -> FALSE | M13: =FALSE() -> FALSE | O13: 0.64710324 | T13: =IF(C13="","",RANK(C13,$C$2:$C$5987)+COUNTIF($C$2:C13,C13)-1) | U13: =IF(I13="","",RANK(I13,$I$2:$I$5987)+COUNTIF($I$2:I13,I13)-1)
A14: 24 Sex b | B14: Confirmed | D14: 0.11 | E14: 0.11 | F14: 1.84 | G14: 0.11 | H14: 0.11 | K14: =FALSE() -> FALSE | L14: =FALSE() -> FALSE | M14: =FALSE() -> FALSE | O14: 1.0438041 | T14: =IF(C14="","",RANK(C14,$C$2:$C$5987)+COUNTIF($C$2:C14,C14)-1) | U14: =IF(I14="","",RANK(I14,$I$2:$I$5987)+COUNTIF($I$2:I14,I14)-1)
A15: 24 Sex c | B15: Confirmed | D15: 0.2 | E15: 0.2 | F15: 1.52 | G15: 0.2 | H15: 0.2 | K15: =FALSE() -> FALSE | L15: =FALSE() -> FALSE | M15: =FALSE() -> FALSE | O15: 0.9242589 | T15: =IF(C15="","",RANK(C15,$C$2:$C$5987)+COUNTIF($C$2:C15,C15)-1) | U15: =IF(I15="","",RANK(I15,$I$2:$I$5987)+COUNTIF($I$2:I15,I15)-1)
A16: 2M 1253+2734 b | B16: Confirmed | D16: 0.2 | E16: 1.8 | F16: 8.3 | G16: 0.2 | H16: 1.8 | K16: =FALSE() -> FALSE | L16: =TRUE() -> TRUE | M16: =FALSE() -> FALSE | O16: 2.2300144 | T16: =IF(C16="","",RANK(C16,$C$2:$C$5987)+COUNTIF($C$2:C16,C16)-1) | U16: =IF(I16="","",RANK(I16,$I$2:$I$5987)+COUNTIF($I$2:I16,I16)-1)
A17: 2M1510 (AB)b | B17: Confirmed | C17: 0.031 | K17: =FALSE() -> FALSE | L17: =FALSE() -> FALSE | M17: =FALSE() -> FALSE | N17: 0.030529205 | T17: =IF(C17="","",RANK(C17,$C$2:$C$5987)+COUNTIF($C$2:C17,C17)-1) -> 1533 | U17: =IF(I17="","",RANK(I17,$I$2:$I$5987)+COUNTIF($I$2:I17,I17)-1)
A18: 2MASS J0437+2651 b | B18: Confirmed | C18: 4 | K18: =TRUE() -> TRUE | L18: =FALSE() -> FALSE | M18: =FALSE() -> FALSE | N18: 1.6094379 | T18: =IF(C18="","",RANK(C18,$C$2:$C$5987)+COUNTIF($C$2:C18,C18)-1) -> 258 | U18: =IF(I18="","",RANK(I18,$I$2:$I$5987)+COUNTIF($I$2:I18,I18)-1)
A19: 2MASS J0558-4501 b | B19: Confirmed | C19: 9 | D19: 3 | E19: 3 | K19: =TRUE() -> TRUE | L19: =FALSE() -> FALSE | M19: =FALSE() -> FALSE | N19: 2.3025851 | T19: =IF(C19="","",RANK(C19,$C$2:$C$5987)+COUNTIF($C$2:C19,C19)-1) -> 79 | U19: =IF(I19="","",RANK(I19,$I$2:$I$5987)+COUNTIF($I$2:I19,I19)-1)
A20: 2MASS J1155-7919 b | B20: Confirmed | C20: 10 | K20: =TRUE() -> TRUE | L20: =FALSE() -> FALSE | M20: =FALSE() -> FALSE | N20: 2.3978953 | T20: =IF(C20="","",RANK(C20,$C$2:$C$5987)+COUNTIF($C$2:C20,C20)-1) -> 56 | U20: =IF(I20="","",RANK(I20,$I$2:$I$5987)+COUNTIF($I$2:I20,I20)-1)
A21: 2MASS J1252+2735 b | B21: Confirmed | D21: 0.64 | E21: 0.21 | F21: 6.88 | G21: 0.64 | H21: 0.21 | K21: =FALSE() -> FALSE | L21: =TRUE() -> TRUE | M21: =FALSE() -> FALSE | O21: 2.0643279 | T21: =IF(C21="","",RANK(C21,$C$2:$C$5987)+COUNTIF($C$2:C21,C21)-1) | U21: =IF(I21="","",RANK(I21,$I$2:$I$5987)+COUNTIF($I$2:I21,I21)-1)
A22: 2MASS J1258+2630 b | B22: Confirmed | D22: 0.18 | E22: 0.31 | F22: 3.4 | G22: 0.18 | H22: 0.31 | K22: =FALSE() -> FALSE | L22: =FALSE() -> FALSE | M22: =FALSE() -> FALSE | O22: 1.4816045 | T22: =IF(C22="","",RANK(C22,$C$2:$C$5987)+COUNTIF($C$2:C22,C22)-1) | U22: =IF(I22="","",RANK(I22,$I$2:$I$5987)+COUNTIF($I$2:I22,I22)-1)
A23: 2MASS J2236+4751 b | B23: Confirmed | C23: 12.5 | D23: 1.5 | E23: 1.5 | K23: =TRUE() -> TRUE | L23: =FALSE() -> FALSE | M23: =FALSE() -> FALSE | N23: 2.6026897 | T23: =IF(C23="","",RANK(C23,$C$2:$C$5987)+COUNTIF($C$2:C23,C23)-1) -> 9 | U23: =IF(I23="","",RANK(I23,$I$2:$I$5987)+COUNTIF($I$2:I23,I23)-1)
A24: 38 Vir b | B24: Confirmed | D24: 0.5 | E24: 0.5 | F24: 4.51 | G24: 0.5 | H24: 0.5 | K24: =FALSE() -> FALSE | L24: =FALSE() -> FALSE | M24: =FALSE() -> FALSE | O24: 1.7065646 | T24: =IF(C24="","",RANK(C24,$C$2:$C$5987)+COUNTIF($C$2:C24,C24)-1) | U24: =IF(I24="","",RANK(I24,$I$2:$I$5987)+COUNTIF($I$2:I24,I24)-1)
A25: 41 Com Ab | B25: Confirmed | D25: 1 | E25: 1 | F25: 6.3 | G25: 1 | H25: 1 | K25: =FALSE() -> FALSE | L25: =TRUE() -> TRUE | M25: =FALSE() -> FALSE | O25: 1.9878743 | T25: =IF(C25="","",RANK(C25,$C$2:$C$5987)+COUNTIF($C$2:C25,C25)-1) | U25: =IF(I25="","",RANK(I25,$I$2:$I$5987)+COUNTIF($I$2:I25,I25)-1)
A26: 44 Uma b | B26: Confirmed | D26: 0.85 | E26: 0.2 | F26: 12.11 | G26: 0.85 | H26: 0.2 | K26: =FALSE() -> FALSE | L26: =TRUE() -> TRUE | M26: =FALSE() -> FALSE | O26: 2.5733753 | T26: =IF(C26="","",RANK(C26,$C$2:$C$5987)+COUNTIF($C$2:C26,C26)-1) | U26: =IF(I26="","",RANK(I26,$I$2:$I$5987)+COUNTIF($I$2:I26,I26)-1)
A27: 47 UMa b | B27: Confirmed | D27: 0.06 | E27: 0.07 | F27: 2.53 | G27: 0.06 | H27: 0.07 | K27: =FALSE() -> FALSE | L27: =FALSE() -> FALSE | M27: =FALSE() -> FALSE | O27: 1.2612979 | T27: =IF(C27="","",RANK(C27,$C$2:$C$5987)+COUNTIF($C$2:C27,C27)-1) | U27: =IF(I27="","",RANK(I27,$I$2:$I$5987)+COUNTIF($I$2:I27,I27)-1)
A28: 47 UMa c | B28: Confirmed | D28: 0.073 | E28: 0.066 | F28: 0.54 | G28: 0.073 | H28: 0.066 | K28: =FALSE() -> FALSE | L28: =FALSE() -> FALSE | M28: =FALSE() -> FALSE | O28: 0.43178242 | T28: =IF(C28="","",RANK(C28,$C$2:$C$5987)+COUNTIF($C$2:C28,C28)-1) | U28: =IF(I28="","",RANK(I28,$I$2:$I$5987)+COUNTIF($I$2:I28,I28)-1)
A29: 47 UMa d | B29: Confirmed | D29: 0.48 | E29: 0.29 | F29: 1.64 | G29: 0.48 | H29: 0.29 | K29: =FALSE() -> FALSE | L29: =FALSE() -> FALSE | M29: =FALSE() -> FALSE | O29: 0.97077892 | T29: =IF(C29="","",RANK(C29,$C$2:$C$5987)+COUNTIF($C$2:C29,C29)-1) | U29: =IF(I29="","",RANK(I29,$I$2:$I$5987)+COUNTIF($I$2:I29,I29)-1)
A30: 51 Eri Ab | B30: Confirmed | C30: 4.1 | D30: 0.5 | E30: 0.5 | I30: 1.11 | J30: 0.13 | K30: =TRUE() -> TRUE | L30: =FALSE() -> FALSE | M30: =TRUE() -> TRUE | N30: 1.6292405 | P30: 0.74668795 | T30: =IF(C30="","",RANK(C30,$C$2:$C$5987)+COUNTIF($C$2:C30,C30)-1) -> 251 | U30: =IF(I30="","",RANK(I30,$I$2:$I$5987)+COUNTIF($I$2:I30,I30)-1) -> 501
A31: 51 Peg b | B31: Confirmed | C31: 0.47 | D31: 0.07 | E31: 0.03 | F31: 0.46 | G31: 0.06 | H31: 0.01 | I31: 1.9 | J31: 0.3 | K31: =FALSE() -> FALSE | L31: =FALSE() -> FALSE | M31: =TRUE() -> TRUE | N31: 0.3852624 | O31: 0.37843644 | P31: 1.0647107 | Q31: -0.33936217 | R31: -0.36062496 | S31: 2.0108302 | T31: =IF(C31="","",RANK(C31,$C$2:$C$5987)+COUNTIF($C$2:C31,C31)-1) -> 968 | U31: =IF(I31="","",RANK(I31,$I$2:$I$5987)+COUNTIF($I$2:I31,I31)-1) -> 18
A32: 54 Psc b | B32: Confirmed | C32: 0.23 | D32: 0.013 | E32: 0.297 | F32: 0.228 | G32: 0.011 | H32: 0.011 | K32: =FALSE() -> FALSE | L32: =FALSE() -> FALSE | M32: =FALSE() -> FALSE | N32: 0.20701417 | O32: 0.20538683 | T32: =IF(C32="","",RANK(C32,$C$2:$C$5987)+COUNTIF($C$2:C32,C32)-1) -> 1126 | U32: =IF(I32="","",RANK(I32,$I$2:$I$5987)+COUNTIF($I$2:I32,I32)-1)
A33: 55 Cnc Ab | B33: Confirmed | C33: 0.84 | D33: 0.031 | E33: 0.23 | F33: 0.84 | G33: 0.031 | H33: 0.131 | K33: =FALSE() -> FALSE | L33: =FALSE() -> FALSE | M33: =FALSE() -> FALSE | N33: 0.60976557 | O33: 0.60976557 | T33: =IF(C33="","",RANK(C33,$C$2:$C$5987)+COUNTIF($C$2:C33,C33)-1) -> 743 | U33: =IF(I33="","",RANK(I33,$I$2:$I$5987)+COUNTIF($I$2:I33,I33)-1)
A34: 55 Cnc Ac | B34: Confirmed | D34: 0.0078 | E34: 0.0275 | F34: 0.1784 | G34: 0.0078 | H34: 0.0275 | K34: =FALSE() -> FALSE | L34: =FALSE() -> FALSE | M34: =FALSE() -> FALSE | O34: 0.16415759 | T34: =IF(C34="","",RANK(C34,$C$2:$C$5987)+COUNTIF($C$2:C34,C34)-1) | U34: =IF(I34="","",RANK(I34,$I$2:$I$5987)+COUNTIF($I$2:I34,I34)-1)
A35: 55 Cnc Ad | B35: Confirmed | D35: 0.08 | E35: 0.08 | F35: 3.84 | G35: 0.08 | H35: 0.08 | K35: =FALSE() -> FALSE | L35: =FALSE() -> FALSE | M35: =FALSE() -> FALSE | O35: 1.5769147 | T35: =IF(C35="","",RANK(C35,$C$2:$C$5987)+COUNTIF($C$2:C35,C35)-1) | U35: =IF(I35="","",RANK(I35,$I$2:$I$5987)+COUNTIF($I$2:I35,I35)-1)
A36: 55 Cnc Ae | B36: Confirmed | C36: 0.02703 | D36: 0.00135 | E36: 0.00135 | I36: 0.1737 | J36: 0.00339 | K36: =FALSE() -> FALSE | L36: =FALSE() -> FALSE | M36: =FALSE() -> FALSE | N36: 0.026671142 | P36: 0.16016115 | T36: =IF(C36="","",RANK(C36,$C$2:$C$5987)+COUNTIF($C$2:C36,C36)-1) -> 1603 | U36: =IF(I36="","",RANK(I36,$I$2:$I$5987)+COUNTIF($I$2:I36,I36)-1) -> 2999
A37: 55 Cnc Af | B37: Confirmed | D37: 0.0093 | E37: 0.0219 | F37: 0.1479 | G37: 0.0093 | H37: 0.0219 | K37: =FALSE() -> FALSE | L37: =FALSE() -> FALSE | M37: =FALSE() -> FALSE | O37: 0.13793419 | T37: =IF(C37="","",RANK(C37,$C$2:$C$5987)+COUNTIF($C$2:C37,C37)-1) | U37: =IF(I37="","",RANK(I37,$I$2:$I$5987)+COUNTIF($I$2:I37,I37)-1)
A38: 61 Vir b | B38: Confirmed | D38: 0.0016 | E38: 0.0016 | F38: 0.016 | G38: 0.0016 | H38: 0.0016 | K38: =FALSE() -> FALSE | L38: =FALSE() -> FALSE | M38: =FALSE() -> FALSE | O38: 0.015873349 | T38: =IF(C38="","",RANK(C38,$C$2:$C$5987)+COUNTIF($C$2:C38,C38)-1) | U38: =IF(I38="","",RANK(I38,$I$2:$I$5987)+COUNTIF($I$2:I38,I38)-1)
A39: 61 Vir c | B39: Confirmed | D39: 0.0035 | E39: 0.0035 | F39: 0.0573 | G39: 0.0035 | H39: 0.0035 | K39: =FALSE() -> FALSE | L39: =FALSE() -> FALSE | M39: =FALSE() -> FALSE | O39: 0.055718489 | T39: =IF(C39="","",RANK(C39,$C$2:$C$5987)+COUNTIF($C$2:C39,C39)-1) | U39: =IF(I39="","",RANK(I39,$I$2:$I$5987)+COUNTIF($I$2:I39,I39)-1)
A40: 61 Vir d | B40: Confirmed | D40: 0.008 | E40: 0.008 | F40: 0.072 | G40: 0.008 | H40: 0.008 | K40: =FALSE() -> FALSE | L40: =FALSE() -> FALSE | M40: =FALSE() -> FALSE | O40: 0.069526063 | T40: =IF(C40="","",RANK(C40,$C$2:$C$5987)+COUNTIF($C$2:C40,C40)-1) | U40: =IF(I40="","",RANK(I40,$I$2:$I$5987)+COUNTIF($I$2:I40,I40)-1)
...

Sheet Summary Statistics
A1: Descriptive Statistics — Mass, Mass·sin(i) & Radius (Jupiter Units)
A3: Metric | B3: Mass (Mj) | C3: Mass·sin(i) (Mj) | D3: Radius (Rj)
A4: Count (non-null) | B4: =COUNT('Cleaned Data'!$C$2:$C$5987) -> 2079 | C4: =COUNT('Cleaned Data'!$F$2:$F$5987) -> 1202 | D4: =COUNT('Cleaned Data'!$I$2:$I$5987) -> 4568
A5: Mean | B5: =AVERAGE('Cleaned Data'!$C$2:$C$5987) -> 1.4925385 | C5: =AVERAGE('Cleaned Data'!$F$2:$F$5987) -> 1.9835288 | D5: =AVERAGE('Cleaned Data'!$I$2:$I$5987) -> 0.40151504
A6: Median | B6: =MEDIAN('Cleaned Data'!$C$2:$C$5987) -> 0.37 | C6: =MEDIAN('Cleaned Data'!$F$2:$F$5987) -> 0.7315 | D6: =MEDIAN('Cleaned Data'!$I$2:$I$5987) -> 0.219
A7: Std. Deviation | B7: =STDEV('Cleaned Data'!$C$2:$C$5987) -> 2.6022857 | C7: =STDEV('Cleaned Data'!$F$2:$F$5987) -> 3.1997172 | D7: =STDEV('Cleaned Data'!$I$2:$I$5987) -> 0.43060129
A8: Variance | B8: =VAR('Cleaned Data'!$C$2:$C$5987) -> 6.7718907 | C8: =VAR('Cleaned Data'!$F$2:$F$5987) -> 10.23819 | D8: =VAR('Cleaned Data'!$I$2:$I$5987) -> 0.18541747
A9: Minimum | B9: =MIN('Cleaned Data'!$C$2:$C$5987) -> 0.00019 | C9: =MIN('Cleaned Data'!$F$2:$F$5987) -> 0.00047 | D9: =MIN('Cleaned Data'!$I$2:$I$5987) -> 0.02543
A10: 1st Quartile (Q1) | B10: =QUARTILE('Cleaned Data'!$C$2:$C$5987,1) -> 0.029655 | C10: =QUARTILE('Cleaned Data'!$F$2:$F$5987,1) -> 0.045 | D10: =QUARTILE('Cleaned Data'!$I$2:$I$5987,1) -> 0.145
A11: 3rd Quartile (Q3) | B11: =QUARTILE('Cleaned Data'!$C$2:$C$5987,3) -> 1.4665 | C11: =QUARTILE('Cleaned Data'!$F$2:$F$5987,3) -> 2.4 | D11: =QUARTILE('Cleaned Data'!$I$2:$I$5987,3) -> 0.384
A12: Maximum | B12: =MAX('Cleaned Data'!$C$2:$C$5987) -> 12.934 | C12: =MAX('Cleaned Data'!$F$2:$F$5987) -> 50 | D12: =MAX('Cleaned Data'!$I$2:$I$5987) -> 6.9
A13: Range | B13: =MAX('Cleaned Data'!$C$2:$C$5987)-MIN('Cleaned Data'!$C$2:$C$5987) -> 12.93381 | C13: =MAX('Cleaned Data'!$F$2:$F$5987)-MIN('Cleaned Data'!$F$2:$F$5987) -> 49.99953 | D13: =MAX('Cleaned Data'!$I$2:$I$5987)-MIN('Cleaned Data'!$I$2:$I$5987) -> 6.87457
A14: Interquartile Range | B14: =QUARTILE('Cleaned Data'!$C$2:$C$5987,3)-QUARTILE('Cleaned Data'!$C$2:$C$5987,1) -> 1.436845 | C14: =QUARTILE('Cleaned Data'!$F$2:$F$5987,3)-QUARTILE('Cleaned Data'!$F$2:$F$5987,1) -> 2.355 | D14: =QUARTILE('Cleaned Data'!$I$2:$I$5987,3)-QUARTILE('Cleaned Data'!$I$2:$I$5987,1) -> 0.239
A15: Coeff. of Variation (%) | B15: =STDEV('Cleaned Data'!$C$2:$C$5987)/AVERAGE('Cleaned Data'!$C$2:$C$5987)*100 -> 174.353 | C15: =STDEV('Cleaned Data'!$F$2:$F$5987)/AVERAGE('Cleaned Data'!$F$2:$F$5987)*100 -> 161.31438 | D15: =STDEV('Cleaned Data'!$I$2:$I$5987)/AVERAGE('Cleaned Data'!$I$2:$I$5987)*100 -> 107.24413
A18: Data Completeness
A19: Field | B19: Non-null Count | C19: Total Rows | D19: Completeness %
A20: Mass | B20: =COUNT('Cleaned Data'!$C$2:$C$5987) -> 2079 | C20: =COUNTA('Cleaned Data'!$A$2:$A$5987) -> 5986 | D20: =B20/C20 -> 0.34731039
A21: Mass·sin(i) | B21: =COUNT('Cleaned Data'!$F$2:$F$5987) -> 1202 | C21: =COUNTA('Cleaned Data'!$A$2:$A$5987) -> 5986 | D21: =B21/C21 -> 0.20080187
A22: Radius | B22: =COUNT('Cleaned Data'!$I$2:$I$5987) -> 4568 | C22: =COUNTA('Cleaned Data'!$A$2:$A$5987) -> 5986 | D22: =B22/C22 -> 0.76311393

Sheet Status Summary
A1: planet_status | B1: Number of Planets
A2: Confirmed | B2: =COUNTIF('Cleaned Data'!$B$2:$B$5987,A2) -> 5986

Sheet Top 10 Planets
A1: Top 10 Planets by Mass and by Radius
A3: Rank | B3: Planet Name | C3: Mass (Mj) | E3: Rank | F3: Planet Name | G3: Radius (Rj)
A4: 1 | B4: {=INDEX('Cleaned Data'!$A$2:$A$5987,MATCH(1,'Cleaned Data'!$T$2:$T$5987,0))} -> GJ 2030 Ac | C4: {=INDEX('Cleaned Data'!$C$2:$C$5987,MATCH(1,'Cleaned Data'!$T$2:$T$5987,0))} -> 12.934 | E4: 1 | F4: {=INDEX('Cleaned Data'!$A$2:$A$5987,MATCH(1,'Cleaned Data'!$U$2:$U$5987,0))} -> HD 100546 b | G4: {=INDEX('Cleaned Data'!$I$2:$I$5987,MATCH(1,'Cleaned Data'!$U$2:$U$5987,0))} -> 6.9
A5: 2 | B5: {=INDEX('Cleaned Data'!$A$2:$A$5987,MATCH(2,'Cleaned Data'!$T$2:$T$5987,0))} -> HATS-70 b | C5: {=INDEX('Cleaned Data'!$C$2:$C$5987,MATCH(2,'Cleaned Data'!$T$2:$T$5987,0))} -> 12.9 | E5: 2 | F5: {=INDEX('Cleaned Data'!$A$2:$A$5987,MATCH(2,'Cleaned Data'!$U$2:$U$5987,0))} -> KOI-7073 b | G5: {=INDEX('Cleaned Data'!$I$2:$I$5987,MATCH(2,'Cleaned Data'!$U$2:$U$5987,0))} -> 2.6987
A6: 3 | B6: {=INDEX('Cleaned Data'!$A$2:$A$5987,MATCH(3,'Cleaned Data'!$T$2:$T$5987,0))} -> TOI-4603 b | C6: {=INDEX('Cleaned Data'!$C$2:$C$5987,MATCH(3,'Cleaned Data'!$T$2:$T$5987,0))} -> 12.89 | E6: 3 | F6: {=INDEX('Cleaned Data'!$A$2:$A$5987,MATCH(3,'Cleaned Data'!$U$2:$U$5987,0))} -> Kepler-450 Ac | G6: {=INDEX('Cleaned Data'!$I$2:$I$5987,MATCH(3,'Cleaned Data'!$U$2:$U$5987,0))} -> 2.59
A7: 4 | B7: {=INDEX('Cleaned Data'!$A$2:$A$5987,MATCH(4,'Cleaned Data'!$T$2:$T$5987,0))} -> HD 11506 d | C7: {=INDEX('Cleaned Data'!$C$2:$C$5987,MATCH(4,'Cleaned Data'!$T$2:$T$5987,0))} -> 12.8 | E7: 4 | F7: {=INDEX('Cleaned Data'!$A$2:$A$5987,MATCH(4,'Cleaned Data'!$U$2:$U$5987,0))} -> ROXs 42B (AB)b | G7: {=INDEX('Cleaned Data'!$I$2:$I$5987,MATCH(4,'Cleaned Data'!$U$2:$U$5987,0))} -> 2.5
A8: 5 | B8: {=INDEX('Cleaned Data'!$A$2:$A$5987,MATCH(5,'Cleaned Data'!$T$2:$T$5987,0))} -> HD 128717 b | C8: {=INDEX('Cleaned Data'!$C$2:$C$5987,MATCH(5,'Cleaned Data'!$T$2:$T$5987,0))} -> 12.8 | E8: 5 | F8: {=INDEX('Cleaned Data'!$A$2:$A$5987,MATCH(5,'Cleaned Data'!$U$2:$U$5987,0))} -> SOI-2 b | G8: {=INDEX('Cleaned Data'!$I$2:$I$5987,MATCH(5,'Cleaned Data'!$U$2:$U$5987,0))} -> 2.22
A9: 6 | B9: {=INDEX('Cleaned Data'!$A$2:$A$5987,MATCH(6,'Cleaned Data'!$T$2:$T$5987,0))} -> TIC 4672985 | C9: {=INDEX('Cleaned Data'!$C$2:$C$5987,MATCH(6,'Cleaned Data'!$T$2:$T$5987,0))} -> 12.74 | E9: 6 | F9: {=INDEX('Cleaned Data'!$A$2:$A$5987,MATCH(6,'Cleaned Data'!$U$2:$U$5987,0))} -> XO-6 b | G9: {=INDEX('Cleaned Data'!$I$2:$I$5987,MATCH(6,'Cleaned Data'!$U$2:$U$5987,0))} -> 2.17
A10: 7 | B10: {=INDEX('Cleaned Data'!$A$2:$A$5987,MATCH(7,'Cleaned Data'!$T$2:$T$5987,0))} -> pi Men b | C10: {=INDEX('Cleaned Data'!$C$2:$C$5987,MATCH(7,'Cleaned Data'!$T$2:$T$5987,0))} -> 12.6 | E10: 7 | F10: {=INDEX('Cleaned Data'!$A$2:$A$5987,MATCH(7,'Cleaned Data'!$U$2:$U$5987,0))} -> HAT-P-67 Ab | G10: {=INDEX('Cleaned Data'!$I$2:$I$5987,MATCH(7,'Cleaned Data'!$U$2:$U$5987,0))} -> 2.14
A11: 8 | B11: {=INDEX('Cleaned Data'!$A$2:$A$5987,MATCH(8,'Cleaned Data'!$T$2:$T$5987,0))} -> HD 149806 Ab | C11: {=INDEX('Cleaned Data'!$C$2:$C$5987,MATCH(8,'Cleaned Data'!$T$2:$T$5987,0))} -> 12.597 | E11: 8 | F11: {=INDEX('Cleaned Data'!$A$2:$A$5987,MATCH(8,'Cleaned Data'!$U$2:$U$5987,0))} -> TOI-3540 b | G11: {=INDEX('Cleaned Data'!$I$2:$I$5987,MATCH(8,'Cleaned Data'!$U$2:$U$5987,0))} -> 2.1
A12: 9 | B12: {=INDEX('Cleaned Data'!$A$2:$A$5987,MATCH(9,'Cleaned Data'!$T$2:$T$5987,0))} -> 2MASS J2236+4751 b | C12: {=INDEX('Cleaned Data'!$C$2:$C$5987,MATCH(9,'Cleaned Data'!$T$2:$T$5987,0))} -> 12.5 | E12: 9 | F12: {=INDEX('Cleaned Data'!$A$2:$A$5987,MATCH(9,'Cleaned Data'!$U$2:$U$5987,0))} -> HIP 65 Ab | G12: {=INDEX('Cleaned Data'!$I$2:$I$5987,MATCH(9,'Cleaned Data'!$U$2:$U$5987,0))} -> 2.03
A13: 10 | B13: {=INDEX('Cleaned Data'!$A$2:$A$5987,MATCH(10,'Cleaned Data'!$T$2:$T$5987,0))} -> TOI-4987 b | C13: {=INDEX('Cleaned Data'!$C$2:$C$5987,MATCH(10,'Cleaned Data'!$T$2:$T$5987,0))} -> 12.37 | E13: 10 | F13: {=INDEX('Cleaned Data'!$A$2:$A$5987,MATCH(10,'Cleaned Data'!$U$2:$U$5987,0))} -> TOI-3807 b | G13: {=INDEX('Cleaned Data'!$I$2:$I$5987,MATCH(10,'Cleaned Data'!$U$2:$U$5987,0))} -> 2

Sheet Mass Classification
A1: Planet Mass Classification (Jupiter Masses, Mj)
A3: Mass Category | B3: Planet Count | C3: Share of Classified (%)
A4: Sub-Neptune (< 0.1 Mj) | B4: =COUNTIF('Cleaned Data'!$C$2:$C$5987,"<0.1") -> 817 | C4: =B4/$B$9 -> 0.39297739
A5: Neptune-like (0.1 – 0.5 Mj) | B5: =COUNTIFS('Cleaned Data'!$C$2:$C$5987,">=0.1",'Cleaned Data'!$C$2:$C$5987,"<0.5") -> 302 | C5: =B5/$B$9 -> 0.14526215
A6: Saturn-like (0.5 – 1 Mj) | B6: =COUNTIFS('Cleaned Data'!$C$2:$C$5987,">=0.5",'Cleaned Data'!$C$2:$C$5987,"<1") -> 296 | C6: =B6/$B$9 -> 0.14237614
A7: Jupiter-like (1 – 2 Mj) | B7: =COUNTIFS('Cleaned Data'!$C$2:$C$5987,">=1",'Cleaned Data'!$C$2:$C$5987,"<2") -> 222 | C7: =B7/$B$9 -> 0.10678211
A8: Super-Jupiter (> 2 Mj) | B8: =COUNTIF('Cleaned Data'!$C$2:$C$5987,">=2") -> 442 | C8: =B8/$B$9 -> 0.21260221
A9: Total Classified | B9: =SUM(B4:B8) -> 2079

Sheet Radius Classification
A1: Planet Radius Classification (Jupiter Radii, Rj)
A3: Radius Category | B3: Planet Count | C3: Share of Classified (%)
A4: Sub-Neptune (< 0.15 Rj) | B4: =COUNTIF('Cleaned Data'!$I$2:$I$5987,"<0.15") -> 1236 | C4: =B4/$B$9 -> 0.27057793
A5: Neptune-size (0.15 – 0.5 Rj) | B5: =COUNTIFS('Cleaned Data'!$I$2:$I$5987,">=0.15",'Cleaned Data'!$I$2:$I$5987,"<0.5") -> 2316 | C5: =B5/$B$9 -> 0.50700525
A6: Saturn-size (0.5 – 0.9 Rj) | B6: =COUNTIFS('Cleaned Data'!$I$2:$I$5987,">=0.5",'Cleaned Data'!$I$2:$I$5987,"<0.9") -> 250 | C6: =B6/$B$9 -> 0.054728546
A7: Jupiter-size (0.9 – 1.3 Rj) | B7: =COUNTIFS('Cleaned Data'!$I$2:$I$5987,">=0.9",'Cleaned Data'!$I$2:$I$5987,"<1.3") -> 505 | C7: =B7/$B$9 -> 0.11055166
A8: Inflated / Large (> 1.3 Rj) | B8: =COUNTIF('Cleaned Data'!$I$2:$I$5987,">=1.3") -> 261 | C8: =B8/$B$9 -> 0.057136602
A9: Total Classified | B9: =SUM(B4:B8) -> 4568

Sheet Outlier Analysis
A1: Outlier Analysis (IQR Method, 1.5×IQR Fences)
A3: Field | B3: Outlier Count | C3: Total Non-null | D3: Outlier %
A4: Mass | B4: =COUNTIF('Cleaned Data'!$K$2:$K$5987,TRUE()) -> 281 | C4: =COUNT('Cleaned Data'!$C$2:$C$5987) -> 2079 | D4: =B4/C4 -> 0.13516114
A5: Mass·sin(i) | B5: =COUNTIF('Cleaned Data'!$L$2:$L$5987,TRUE()) -> 126 | C5: =COUNT('Cleaned Data'!$F$2:$F$5987) -> 1202 | D5: =B5/C5 -> 0.10482529
A6: Radius | B6: =COUNTIF('Cleaned Data'!$M$2:$M$5987,TRUE()) -> 876 | C6: =COUNT('Cleaned Data'!$I$2:$I$5987) -> 4568 | D6: =B6/C6 -> 0.19176883

Sheet Chart Data
A1: Planet Status | B1: Number of Planets | C1: Percentage | E1: Rank | F1: Planet Name | G1: Mass
A2: Confirmed | B2: 1588 | C2: 1 | E2: 1 | F2: HATS-70 b | G2: 12.9
E3: 2 | F3: TOI-4603 b | G3: 12.89
E4: 3 | F4: TIC 4672985 | G4: 12.74
E5: 4 | F5: TOI-4987 b | G5: 12.37
E6: 5 | F6: HD 31221 b | G6: 12
E7: 6 | F7: beta Pic b | G7: 11.9
E8: 7 | F8: XO-3 Ab | G8: 11.79
E9: 8 | F9: Kepler-1625 b | G9: 11.6
E10: 9 | F10: Ross 458 (AB)b | G10: 11.3
E11: 10 | F11: GU Psc b | G11: 11

Sheet Mass vs Radius
A1: Planet Name | B1: Mass | C1: Radius
A2: 109 Psc b | B2: 5.743 | C2: 1.152
A3: 51 Eri Ab | B3: 4.1 | C3: 1.11
A4: 51 Peg b | B4: 0.47 | C4: 1.9
A5: 55 Cnc Ae | B5: 0.02703 | C5: 0.1737
A6: AF Lep b | B6: 3.75 | C6: 1.3
A7: AU Mic b | B7: 0.028 | C7: 0.4273
A8: AU Mic c | B8: 0.0456 | C8: 0.2248
A9: BD+20 594 b | B9: 0.07 | C9: 0.23
A10: beta Pic b | B10: 11.9 | C10: 1.65
A11: beta Pic c | B11: 8.89 | C11: 1.2
A12: CFHTWIR-Oph 98 b | B12: 7.8 | C12: 1.86
A13: COCONUTS-2 b | B13: 6.4 | C13: 1.12
... A1589: XO-7 b | B1589: 0.726 | C1589: 1.346
